Workbook

Sheet Data Umum
B2: B
B3: LBPDG | C3: Data Umum | G3: =MONTH(D11) | H3: 1 | I3: Januari
B4: PGAKD | C4: Versi Laporan | D4: 2/7/2025 11:28:37 AM | G4: =VLOOKUP(G3,$H$3:$I$14,2,FALSE) | H4: 2 | I4: Februari
B5: 1 | C5: Tanggal Pelaporan | D5: 45762 | H5: 3 | I5: Maret
B6: N | C6: Kode Perusahaan / Pihak | D6: 2000018923 | H6: 4 | I6: April
C7: Nama Perusahaan / Pihak | D7: PT Tumbuh Bersama Nano | H7: 5 | I7: Mei
C8: Alamat Perusahaan / Pihak | D8: Mayapada Tower 1, Lantai 20, Suite 03A, | H8: 6 | I8: Juni
D9: Jl. Jendral Sudirman KAav 28 Kuningan Karet, | H9: 7 | I9: Juli
D10: Setiabudi, Jakarta Selatan, 12920 | H10: 8 | I10: Agustus
C11: Periode Pelaporan | D11: 45747 | H11: 9 | I11: September
C12: Bulan Pelaporan | D12: =IF(ISERR(G4), "", G4) | H12: 10 | I12: Oktober
C13: Tahun Fiskal | D13: =IF(ISBLANK(D11), "", IFERROR(YEAR(D11), "")) | H13: 11 | I13: November
C14: Jenis Periode Pelaporan | D14: Laporan Bulanan | H14: 12 | I14: Desember
C15: Nama Direksi / Penanggung Jawab | D15: Billy Surya Jaya
C16: Jabatan Direksi / Penanggung Jawab | D16: Direktur Utama

Sheet Cover
C7: K e p a d a
C9: Yth.Kepala Departemen Pengawasan Aset Keuangan Digital dan Aset Kripto
C10: Otoritas Jasa Keuangan
C11: Keuangan, Aset Keuangan Digital dan Aset Kripto
C12: Gedung Soemitro Djojohadikusumo
C13: Jalan Lapangan Banteng Timur 2-4, Jakarta 10710, Indonesia
C20: LAPORAN BULANAN
C21: PEDAGANG ASET KEUANGAN
C22: =""
C30: =UPPER('Data Umum'!D7)
C31: =IF('Data Umum'!D8=0, "", 'Data Umum'!D8)
C32: =IF('Data Umum'!D9=0, "", 'Data Umum'!D9)
C33: =IF('Data Umum'!D10=0, "", 'Data Umum'!D10)

Sheet Validasi
C7: Status | E7: Status Validitas Laporan Secara Keseluruhan | G7: =AND(G10, G11, G12, G13, G14, G15, G16, G17, G18, G19, G20, G21, G22, G23, G24, G25, G26, G27, G28, G29, G30, G31, G32, G33, G34, G35, G36, G37, G38, G39, G40, G41, G42, G43, G44, G45, G46, G47, G48, G49, G50, G51, G52, G53, G54, G55, G56, G57, G58, G59, G60, G61, G62, G63, G64, G65, G66, G67, G68, G69)
C9: No | D9: Sheet | E9: Keterangan | F9: Formula | G9: Status
C10: 1 | D10: LRTTHP | E10: Jika Jenis Konsumen tidak sesuai dengan Jenis Identitas yang ditentukan, di mana "Individu" hanya dapat memilih NIK/National ID dan "Badan Usaha" hanya dapat memilih NPWP/Identification No./Tax ID/Sejenis | F10: =IF(OR(AND(LRTTHP!$I$16="individu ",LRTTHP!$E$16="NIK (Domestik)"),AND(LRTTHP!$I$16="individu ",LRTTHP!$E$16="National ID (Asing)"),AND(LRTTHP!$I$16="Badan Usaha",LRTTHP!$E$16="NPWP (Domestik)"),AND(LRTTHP!$I$16="Badan Usaha",LRTTHP!$E$16="Identification No./ Tax Id/Sejenis (Asing)")),TRUE,FALSE) | G10: =IF(OR(AND(LRTTHP!$I$16="individu ",LRTTHP!$E$16="NIK (Domestik)"),AND(LRTTHP!$I$16="individu ",LRTTHP!$E$16="National ID (Asing)"),AND(LRTTHP!$I$16="Badan Usaha",LRTTHP!$E$16="NPWP (Domestik)"),AND(LRTTHP!$I$16="Badan Usaha",LRTTHP!$E$16="Identification No./ Tax Id/Sejenis (Asing)")),TRUE,FALSE)
C11: 2 | D11: LRTTHP | E11: Jika Jenis Konsumen tidak sesuai dengan Jenis Identitas yang ditentukan, di mana "Individu" hanya dapat memilih NIK/National ID dan "Badan Usaha" hanya dapat memilih NPWP/Identification No./Tax ID/Sejenis | F11: =IF(OR(AND(LRTTHP!$I$17="individu ",LRTTHP!$E$17="NIK (Domestik)"),AND(LRTTHP!$I$17="individu ",LRTTHP!$E$17="National ID (Asing)"),AND(LRTTHP!$I$17="Badan Usaha",LRTTHP!$E$17="NPWP (Domestik)"),AND(LRTTHP!$I$17="Badan Usaha",LRTTHP!$E$17="Identification No./ Tax Id/Sejenis (Asing)")),TRUE,FALSE) | G11: =IF(OR(AND(LRTTHP!$I$17="individu ",LRTTHP!$E$17="NIK (Domestik)"),AND(LRTTHP!$I$17="individu ",LRTTHP!$E$17="National ID (Asing)"),AND(LRTTHP!$I$17="Badan Usaha",LRTTHP!$E$17="NPWP (Domestik)"),AND(LRTTHP!$I$17="Badan Usaha",LRTTHP!$E$17="Identification No./ Tax Id/Sejenis (Asing)")),TRUE,FALSE)
C12: 3 | D12: LRTTHP | E12: Jika Jenis Konsumen tidak sesuai dengan Jenis Identitas yang ditentukan, di mana "Individu" hanya dapat memilih NIK/National ID dan "Badan Usaha" hanya dapat memilih NPWP/Identification No./Tax ID/Sejenis | F12: =IF(OR(AND(LRTTHP!$I$18="individu ",LRTTHP!$E$18="NIK (Domestik)"),AND(LRTTHP!$I$18="individu ",LRTTHP!$E$18="National ID (Asing)"),AND(LRTTHP!$I$18="Badan Usaha",LRTTHP!$E$18="NPWP (Domestik)"),AND(LRTTHP!$I$18="Badan Usaha",LRTTHP!$E$18="Identification No./ Tax Id/Sejenis (Asing)")),TRUE,FALSE) | G12: =IF(OR(AND(LRTTHP!$I$18="individu ",LRTTHP!$E$18="NIK (Domestik)"),AND(LRTTHP!$I$18="individu ",LRTTHP!$E$18="National ID (Asing)"),AND(LRTTHP!$I$18="Badan Usaha",LRTTHP!$E$18="NPWP (Domestik)"),AND(LRTTHP!$I$18="Badan Usaha",LRTTHP!$E$18="Identification No./ Tax Id/Sejenis (Asing)")),TRUE,FALSE)
C13: 4 | D13: LRTTHP | E13: Jika Jenis Konsumen tidak sesuai dengan Jenis Identitas yang ditentukan, di mana "Individu" hanya dapat memilih NIK/National ID dan "Badan Usaha" hanya dapat memilih NPWP/Identification No./Tax ID/Sejenis | F13: =IF(OR(AND(LRTTHP!$I$19="individu ",LRTTHP!$E$19="NIK (Domestik)"),AND(LRTTHP!$I$19="individu ",LRTTHP!$E$19="National ID (Asing)"),AND(LRTTHP!$I$19="Badan Usaha",LRTTHP!$E$19="NPWP (Domestik)"),AND(LRTTHP!$I$19="Badan Usaha",LRTTHP!$E$19="Identification No./ Tax Id/Sejenis (Asing)")),TRUE,FALSE) | G13: =IF(OR(AND(LRTTHP!$I$19="individu ",LRTTHP!$E$19="NIK (Domestik)"),AND(LRTTHP!$I$19="individu ",LRTTHP!$E$19="National ID (Asing)"),AND(LRTTHP!$I$19="Badan Usaha",LRTTHP!$E$19="NPWP (Domestik)"),AND(LRTTHP!$I$19="Badan Usaha",LRTTHP!$E$19="Identification No./ Tax Id/Sejenis (Asing)")),TRUE,FALSE)
C14: 5 | D14: LRTTHP | E14: Jika Jenis Konsumen tidak sesuai dengan Jenis Identitas yang ditentukan, di mana "Individu" hanya dapat memilih NIK/National ID dan "Badan Usaha" hanya dapat memilih NPWP/Identification No./Tax ID/Sejenis | F14: =IF(OR(AND(LRTTHP!$I$20="individu ",LRTTHP!$E$20="NIK (Domestik)"),AND(LRTTHP!$I$20="individu ",LRTTHP!$E$20="National ID (Asing)"),AND(LRTTHP!$I$20="Badan Usaha",LRTTHP!$E$20="NPWP (Domestik)"),AND(LRTTHP!$I$20="Badan Usaha",LRTTHP!$E$20="Identification No./ Tax Id/Sejenis (Asing)")),TRUE,FALSE) | G14: =IF(OR(AND(LRTTHP!$I$20="individu ",LRTTHP!$E$20="NIK (Domestik)"),AND(LRTTHP!$I$20="individu ",LRTTHP!$E$20="National ID (Asing)"),AND(LRTTHP!$I$20="Badan Usaha",LRTTHP!$E$20="NPWP (Domestik)"),AND(LRTTHP!$I$20="Badan Usaha",LRTTHP!$E$20="Identification No./ Tax Id/Sejenis (Asing)")),TRUE,FALSE)
C15: 6 | D15: LRTTHP | E15: Jika Jenis Konsumen tidak sesuai dengan Jenis Identitas yang ditentukan, di mana "Individu" hanya dapat memilih NIK/National ID dan "Badan Usaha" hanya dapat memilih NPWP/Identification No./Tax ID/Sejenis | F15: =IF(OR(AND(LRTTHP!$I$21="individu ",LRTTHP!$E$21="NIK (Domestik)"),AND(LRTTHP!$I$21="individu ",LRTTHP!$E$21="National ID (Asing)"),AND(LRTTHP!$I$21="Badan Usaha",LRTTHP!$E$21="NPWP (Domestik)"),AND(LRTTHP!$I$21="Badan Usaha",LRTTHP!$E$21="Identification No./ Tax Id/Sejenis (Asing)")),TRUE,FALSE) | G15: =IF(OR(AND(LRTTHP!$I$21="individu ",LRTTHP!$E$21="NIK (Domestik)"),AND(LRTTHP!$I$21="individu ",LRTTHP!$E$21="National ID (Asing)"),AND(LRTTHP!$I$21="Badan Usaha",LRTTHP!$E$21="NPWP (Domestik)"),AND(LRTTHP!$I$21="Badan Usaha",LRTTHP!$E$21="Identification No./ Tax Id/Sejenis (Asing)")),TRUE,FALSE)
C16: 7 | D16: LRTTHP | E16: Jika Jenis Konsumen tidak sesuai dengan Jenis Identitas yang ditentukan, di mana "Individu" hanya dapat memilih NIK/National ID dan "Badan Usaha" hanya dapat memilih NPWP/Identification No./Tax ID/Sejenis | F16: =IF(OR(AND(LRTTHP!$I$22="individu ",LRTTHP!$E$22="NIK (Domestik)"),AND(LRTTHP!$I$22="individu ",LRTTHP!$E$22="National ID (Asing)"),AND(LRTTHP!$I$22="Badan Usaha",LRTTHP!$E$22="NPWP (Domestik)"),AND(LRTTHP!$I$22="Badan Usaha",LRTTHP!$E$22="Identification No./ Tax Id/Sejenis (Asing)")),TRUE,FALSE) | G16: =IF(OR(AND(LRTTHP!$I$22="individu ",LRTTHP!$E$22="NIK (Domestik)"),AND(LRTTHP!$I$22="individu ",LRTTHP!$E$22="National ID (Asing)"),AND(LRTTHP!$I$22="Badan Usaha",LRTTHP!$E$22="NPWP (Domestik)"),AND(LRTTHP!$I$22="Badan Usaha",LRTTHP!$E$22="Identification No./ Tax Id/Sejenis (Asing)")),TRUE,FALSE)
C17: 8 | D17: LRTTHP | E17: Jika Jenis Konsumen tidak sesuai dengan Jenis Identitas yang ditentukan, di mana "Individu" hanya dapat memilih NIK/National ID dan "Badan Usaha" hanya dapat memilih NPWP/Identification No./Tax ID/Sejenis | F17: =IF(OR(AND(LRTTHP!$I$23="individu ",LRTTHP!$E$23="NIK (Domestik)"),AND(LRTTHP!$I$23="individu ",LRTTHP!$E$23="National ID (Asing)"),AND(LRTTHP!$I$23="Badan Usaha",LRTTHP!$E$23="NPWP (Domestik)"),AND(LRTTHP!$I$23="Badan Usaha",LRTTHP!$E$23="Identification No./ Tax Id/Sejenis (Asing)")),TRUE,FALSE) | G17: =IF(OR(AND(LRTTHP!$I$23="individu ",LRTTHP!$E$23="NIK (Domestik)"),AND(LRTTHP!$I$23="individu ",LRTTHP!$E$23="National ID (Asing)"),AND(LRTTHP!$I$23="Badan Usaha",LRTTHP!$E$23="NPWP (Domestik)"),AND(LRTTHP!$I$23="Badan Usaha",LRTTHP!$E$23="Identification No./ Tax Id/Sejenis (Asing)")),TRUE,FALSE)
C18: 9 | D18: LRTTHP | E18: Jika Jenis Konsumen tidak sesuai dengan Jenis Identitas yang ditentukan, di mana "Individu" hanya dapat memilih NIK/National ID dan "Badan Usaha" hanya dapat memilih NPWP/Identification No./Tax ID/Sejenis | F18: =IF(OR(AND(LRTTHP!$I$24="individu ",LRTTHP!$E$24="NIK (Domestik)"),AND(LRTTHP!$I$24="individu ",LRTTHP!$E$24="National ID (Asing)"),AND(LRTTHP!$I$24="Badan Usaha",LRTTHP!$E$24="NPWP (Domestik)"),AND(LRTTHP!$I$24="Badan Usaha",LRTTHP!$E$24="Identification No./ Tax Id/Sejenis (Asing)")),TRUE,FALSE) | G18: =IF(OR(AND(LRTTHP!$I$24="individu ",LRTTHP!$E$24="NIK (Domestik)"),AND(LRTTHP!$I$24="individu ",LRTTHP!$E$24="National ID (Asing)"),AND(LRTTHP!$I$24="Badan Usaha",LRTTHP!$E$24="NPWP (Domestik)"),AND(LRTTHP!$I$24="Badan Usaha",LRTTHP!$E$24="Identification No./ Tax Id/Sejenis (Asing)")),TRUE,FALSE)
C19: 10 | D19: LRTTHP | E19: Jika Jenis Konsumen tidak sesuai dengan Jenis Identitas yang ditentukan, di mana "Individu" hanya dapat memilih NIK/National ID dan "Badan Usaha" hanya dapat memilih NPWP/Identification No./Tax ID/Sejenis | F19: =IF(OR(AND(LRTTHP!$I$25="individu ",LRTTHP!$E$25="NIK (Domestik)"),AND(LRTTHP!$I$25="individu ",LRTTHP!$E$25="National ID (Asing)"),AND(LRTTHP!$I$25="Badan Usaha",LRTTHP!$E$25="NPWP (Domestik)"),AND(LRTTHP!$I$25="Badan Usaha",LRTTHP!$E$25="Identification No./ Tax Id/Sejenis (Asing)")),TRUE,FALSE) | G19: =IF(OR(AND(LRTTHP!$I$25="individu ",LRTTHP!$E$25="NIK (Domestik)"),AND(LRTTHP!$I$25="individu ",LRTTHP!$E$25="National ID (Asing)"),AND(LRTTHP!$I$25="Badan Usaha",LRTTHP!$E$25="NPWP (Domestik)"),AND(LRTTHP!$I$25="Badan Usaha",LRTTHP!$E$25="Identification No./ Tax Id/Sejenis (Asing)")),TRUE,FALSE)
C20: 11 | D20: LRTTHP | E20: Jika Jenis Konsumen tidak sesuai dengan Jenis Identitas yang ditentukan, di mana "Individu" hanya dapat memilih NIK/National ID dan "Badan Usaha" hanya dapat memilih NPWP/Identification No./Tax ID/Sejenis | F20: =IF(OR(AND(LRTTHP!$I$26="individu ",LRTTHP!$E$26="NIK (Domestik)"),AND(LRTTHP!$I$26="individu ",LRTTHP!$E$26="National ID (Asing)"),AND(LRTTHP!$I$26="Badan Usaha",LRTTHP!$E$26="NPWP (Domestik)"),AND(LRTTHP!$I$26="Badan Usaha",LRTTHP!$E$26="Identification No./ Tax Id/Sejenis (Asing)")),TRUE,FALSE) | G20: =IF(OR(AND(LRTTHP!$I$26="individu ",LRTTHP!$E$26="NIK (Domestik)"),AND(LRTTHP!$I$26="individu ",LRTTHP!$E$26="National ID (Asing)"),AND(LRTTHP!$I$26="Badan Usaha",LRTTHP!$E$26="NPWP (Domestik)"),AND(LRTTHP!$I$26="Badan Usaha",LRTTHP!$E$26="Identification No./ Tax Id/Sejenis (Asing)")),TRUE,FALSE)
C21: 12 | D21: LRTTHP | E21: Jika Jenis Konsumen tidak sesuai dengan Jenis Identitas yang ditentukan, di mana "Individu" hanya dapat memilih NIK/National ID dan "Badan Usaha" hanya dapat memilih NPWP/Identification No./Tax ID/Sejenis | F21: =IF(OR(AND(LRTTHP!$I$27="individu ",LRTTHP!$E$27="NIK (Domestik)"),AND(LRTTHP!$I$27="individu ",LRTTHP!$E$27="National ID (Asing)"),AND(LRTTHP!$I$27="Badan Usaha",LRTTHP!$E$27="NPWP (Domestik)"),AND(LRTTHP!$I$27="Badan Usaha",LRTTHP!$E$27="Identification No./ Tax Id/Sejenis (Asing)")),TRUE,FALSE) | G21: =IF(OR(AND(LRTTHP!$I$27="individu ",LRTTHP!$E$27="NIK (Domestik)"),AND(LRTTHP!$I$27="individu ",LRTTHP!$E$27="National ID (Asing)"),AND(LRTTHP!$I$27="Badan Usaha",LRTTHP!$E$27="NPWP (Domestik)"),AND(LRTTHP!$I$27="Badan Usaha",LRTTHP!$E$27="Identification No./ Tax Id/Sejenis (Asing)")),TRUE,FALSE)
C22: 13 | D22: LRTTHP | E22: Jika Jenis Konsumen tidak sesuai dengan Jenis Identitas yang ditentukan, di mana "Individu" hanya dapat memilih NIK/National ID dan "Badan Usaha" hanya dapat memilih NPWP/Identification No./Tax ID/Sejenis | F22: =IF(OR(AND(LRTTHP!$I$28="individu ",LRTTHP!$E$28="NIK (Domestik)"),AND(LRTTHP!$I$28="individu ",LRTTHP!$E$28="National ID (Asing)"),AND(LRTTHP!$I$28="Badan Usaha",LRTTHP!$E$28="NPWP (Domestik)"),AND(LRTTHP!$I$28="Badan Usaha",LRTTHP!$E$28="Identification No./ Tax Id/Sejenis (Asing)")),TRUE,FALSE) | G22: =IF(OR(AND(LRTTHP!$I$28="individu ",LRTTHP!$E$28="NIK (Domestik)"),AND(LRTTHP!$I$28="individu ",LRTTHP!$E$28="National ID (Asing)"),AND(LRTTHP!$I$28="Badan Usaha",LRTTHP!$E$28="NPWP (Domestik)"),AND(LRTTHP!$I$28="Badan Usaha",LRTTHP!$E$28="Identification No./ Tax Id/Sejenis (Asing)")),TRUE,FALSE)
C23: 14 | D23: LRTTHP | E23: Jika Jenis Konsumen tidak sesuai dengan Jenis Identitas yang ditentukan, di mana "Individu" hanya dapat memilih NIK/National ID dan "Badan Usaha" hanya dapat memilih NPWP/Identification No./Tax ID/Sejenis | F23: =IF(OR(AND(LRTTHP!$I$29="individu ",LRTTHP!$E$29="NIK (Domestik)"),AND(LRTTHP!$I$29="individu ",LRTTHP!$E$29="National ID (Asing)"),AND(LRTTHP!$I$29="Badan Usaha",LRTTHP!$E$29="NPWP (Domestik)"),AND(LRTTHP!$I$29="Badan Usaha",LRTTHP!$E$29="Identification No./ Tax Id/Sejenis (Asing)")),TRUE,FALSE) | G23: =IF(OR(AND(LRTTHP!$I$29="individu ",LRTTHP!$E$29="NIK (Domestik)"),AND(LRTTHP!$I$29="individu ",LRTTHP!$E$29="National ID (Asing)"),AND(LRTTHP!$I$29="Badan Usaha",LRTTHP!$E$29="NPWP (Domestik)"),AND(LRTTHP!$I$29="Badan Usaha",LRTTHP!$E$29="Identification No./ Tax Id/Sejenis (Asing)")),TRUE,FALSE)
C24: 15 | D24: LRTTHP | E24: Jika Jenis Konsumen tidak sesuai dengan Jenis Identitas yang ditentukan, di mana "Individu" hanya dapat memilih NIK/National ID dan "Badan Usaha" hanya dapat memilih NPWP/Identification No./Tax ID/Sejenis | F24: =IF(OR(AND(LRTTHP!$I$30="individu ",LRTTHP!$E$30="NIK (Domestik)"),AND(LRTTHP!$I$30="individu ",LRTTHP!$E$30="National ID (Asing)"),AND(LRTTHP!$I$30="Badan Usaha",LRTTHP!$E$30="NPWP (Domestik)"),AND(LRTTHP!$I$30="Badan Usaha",LRTTHP!$E$30="Identification No./ Tax Id/Sejenis (Asing)")),TRUE,FALSE) | G24: =IF(OR(AND(LRTTHP!$I$30="individu ",LRTTHP!$E$30="NIK (Domestik)"),AND(LRTTHP!$I$30="individu ",LRTTHP!$E$30="National ID (Asing)"),AND(LRTTHP!$I$30="Badan Usaha",LRTTHP!$E$30="NPWP (Domestik)"),AND(LRTTHP!$I$30="Badan Usaha",LRTTHP!$E$30="Identification No./ Tax Id/Sejenis (Asing)")),TRUE,FALSE)
C25: 16 | D25: LRTTHP | E25: Jika Jenis Konsumen tidak sesuai dengan Jenis Identitas yang ditentukan, di mana "Individu" hanya dapat memilih NIK/National ID dan "Badan Usaha" hanya dapat memilih NPWP/Identification No./Tax ID/Sejenis | F25: =IF(OR(AND(LRTTHP!$I$31="individu ",LRTTHP!$E$31="NIK (Domestik)"),AND(LRTTHP!$I$31="individu ",LRTTHP!$E$31="National ID (Asing)"),AND(LRTTHP!$I$31="Badan Usaha",LRTTHP!$E$31="NPWP (Domestik)"),AND(LRTTHP!$I$31="Badan Usaha",LRTTHP!$E$31="Identification No./ Tax Id/Sejenis (Asing)")),TRUE,FALSE) | G25: =IF(OR(AND(LRTTHP!$I$31="individu ",LRTTHP!$E$31="NIK (Domestik)"),AND(LRTTHP!$I$31="individu ",LRTTHP!$E$31="National ID (Asing)"),AND(LRTTHP!$I$31="Badan Usaha",LRTTHP!$E$31="NPWP (Domestik)"),AND(LRTTHP!$I$31="Badan Usaha",LRTTHP!$E$31="Identification No./ Tax Id/Sejenis (Asing)")),TRUE,FALSE)
C26: 17 | D26: LRTTHP | E26: Jika Jenis Konsumen tidak sesuai dengan Jenis Identitas yang ditentukan, di mana "Individu" hanya dapat memilih NIK/National ID dan "Badan Usaha" hanya dapat memilih NPWP/Identification No./Tax ID/Sejenis | F26: =IF(OR(AND(LRTTHP!$I$32="individu ",LRTTHP!$E$32="NIK (Domestik)"),AND(LRTTHP!$I$32="individu ",LRTTHP!$E$32="National ID (Asing)"),AND(LRTTHP!$I$32="Badan Usaha",LRTTHP!$E$32="NPWP (Domestik)"),AND(LRTTHP!$I$32="Badan Usaha",LRTTHP!$E$32="Identification No./ Tax Id/Sejenis (Asing)")),TRUE,FALSE) | G26: =IF(OR(AND(LRTTHP!$I$32="individu ",LRTTHP!$E$32="NIK (Domestik)"),AND(LRTTHP!$I$32="individu ",LRTTHP!$E$32="National ID (Asing)"),AND(LRTTHP!$I$32="Badan Usaha",LRTTHP!$E$32="NPWP (Domestik)"),AND(LRTTHP!$I$32="Badan Usaha",LRTTHP!$E$32="Identification No./ Tax Id/Sejenis (Asing)")),TRUE,FALSE)
C27: 18 | D27: LRTTHP | E27: Jika Jenis Konsumen tidak sesuai dengan Jenis Identitas yang ditentukan, di mana "Individu" hanya dapat memilih NIK/National ID dan "Badan Usaha" hanya dapat memilih NPWP/Identification No./Tax ID/Sejenis | F27: =IF(OR(AND(LRTTHP!$I$33="individu ",LRTTHP!$E$33="NIK (Domestik)"),AND(LRTTHP!$I$33="individu ",LRTTHP!$E$33="National ID (Asing)"),AND(LRTTHP!$I$33="Badan Usaha",LRTTHP!$E$33="NPWP (Domestik)"),AND(LRTTHP!$I$33="Badan Usaha",LRTTHP!$E$33="Identification No./ Tax Id/Sejenis (Asing)")),TRUE,FALSE) | G27: =IF(OR(AND(LRTTHP!$I$33="individu ",LRTTHP!$E$33="NIK (Domestik)"),AND(LRTTHP!$I$33="individu ",LRTTHP!$E$33="National ID (Asing)"),AND(LRTTHP!$I$33="Badan Usaha",LRTTHP!$E$33="NPWP (Domestik)"),AND(LRTTHP!$I$33="Badan Usaha",LRTTHP!$E$33="Identification No./ Tax Id/Sejenis (Asing)")),TRUE,FALSE)
C28: 19 | D28: LRTTHP | E28: Jika Jenis Konsumen tidak sesuai dengan Jenis Identitas yang ditentukan, di mana "Individu" hanya dapat memilih NIK/National ID dan "Badan Usaha" hanya dapat memilih NPWP/Identification No./Tax ID/Sejenis | F28: =IF(OR(AND(LRTTHP!$I$34="individu ",LRTTHP!$E$34="NIK (Domestik)"),AND(LRTTHP!$I$34="individu ",LRTTHP!$E$34="National ID (Asing)"),AND(LRTTHP!$I$34="Badan Usaha",LRTTHP!$E$34="NPWP (Domestik)"),AND(LRTTHP!$I$34="Badan Usaha",LRTTHP!$E$34="Identification No./ Tax Id/Sejenis (Asing)")),TRUE,FALSE) | G28: =IF(OR(AND(LRTTHP!$I$34="individu ",LRTTHP!$E$34="NIK (Domestik)"),AND(LRTTHP!$I$34="individu ",LRTTHP!$E$34="National ID (Asing)"),AND(LRTTHP!$I$34="Badan Usaha",LRTTHP!$E$34="NPWP (Domestik)"),AND(LRTTHP!$I$34="Badan Usaha",LRTTHP!$E$34="Identification No./ Tax Id/Sejenis (Asing)")),TRUE,FALSE)
C29: 20 | D29: LRTTHP | E29: Jika Jenis Konsumen tidak sesuai dengan Jenis Identitas yang ditentukan, di mana "Individu" hanya dapat memilih NIK/National ID dan "Badan Usaha" hanya dapat memilih NPWP/Identification No./Tax ID/Sejenis | F29: =IF(OR(AND(LRTTHP!$I$35="individu ",LRTTHP!$E$35="NIK (Domestik)"),AND(LRTTHP!$I$35="individu ",LRTTHP!$E$35="National ID (Asing)"),AND(LRTTHP!$I$35="Badan Usaha",LRTTHP!$E$35="NPWP (Domestik)"),AND(LRTTHP!$I$35="Badan Usaha",LRTTHP!$E$35="Identification No./ Tax Id/Sejenis (Asing)")),TRUE,FALSE) | G29: =IF(OR(AND(LRTTHP!$I$35="individu ",LRTTHP!$E$35="NIK (Domestik)"),AND(LRTTHP!$I$35="individu ",LRTTHP!$E$35="National ID (Asing)"),AND(LRTTHP!$I$35="Badan Usaha",LRTTHP!$E$35="NPWP (Domestik)"),AND(LRTTHP!$I$35="Badan Usaha",LRTTHP!$E$35="Identification No./ Tax Id/Sejenis (Asing)")),TRUE,FALSE)
C30: 21 | D30: LRTTOPA | E30: Jika Jenis Konsumen tidak sesuai dengan Jenis Identitas yang ditentukan, di mana "Individu" hanya dapat memilih NIK/National ID dan "Badan Usaha" hanya dapat memilih NPWP/Identification No./Tax ID/Sejenis | F30: =IF(OR(AND(LRTTOPA!$I$16="individu ",LRTTOPA!$E$16="NIK (Domestik)"),AND(LRTTOPA!$I$16="individu ",LRTTOPA!$E$16="National ID (Asing)"),AND(LRTTOPA!$I$16="Badan Usaha",LRTTOPA!$E$16="NPWP (Domestik)"),AND(LRTTOPA!$I$16="Badan Usaha",LRTTOPA!$E$16="Identification No./ Tax Id/Sejenis (Asing)")),TRUE,FALSE) | G30: =IF(OR(AND(LRTTOPA!$I$16="individu ",LRTTOPA!$E$16="NIK (Domestik)"),AND(LRTTOPA!$I$16="individu ",LRTTOPA!$E$16="National ID (Asing)"),AND(LRTTOPA!$I$16="Badan Usaha",LRTTOPA!$E$16="NPWP (Domestik)"),AND(LRTTOPA!$I$16="Badan Usaha",LRTTOPA!$E$16="Identification No./ Tax Id/Sejenis (Asing)")),TRUE,FALSE)
C31: 22 | D31: LRTTOPA | E31: Jika Jenis Konsumen tidak sesuai dengan Jenis Identitas yang ditentukan, di mana "Individu" hanya dapat memilih NIK/National ID dan "Badan Usaha" hanya dapat memilih NPWP/Identification No./Tax ID/Sejenis | F31: =IF(OR(AND(LRTTOPA!$I$17="individu ",LRTTOPA!$E$17="NIK (Domestik)"),AND(LRTTOPA!$I$17="individu ",LRTTOPA!$E$17="National ID (Asing)"),AND(LRTTOPA!$I$17="Badan Usaha",LRTTOPA!$E$17="NPWP (Domestik)"),AND(LRTTOPA!$I$17="Badan Usaha",LRTTOPA!$E$17="Identification No./ Tax Id/Sejenis (Asing)")),TRUE,FALSE) | G31: =IF(OR(AND(LRTTOPA!$I$17="individu ",LRTTOPA!$E$17="NIK (Domestik)"),AND(LRTTOPA!$I$17="individu ",LRTTOPA!$E$17="National ID (Asing)"),AND(LRTTOPA!$I$17="Badan Usaha",LRTTOPA!$E$17="NPWP (Domestik)"),AND(LRTTOPA!$I$17="Badan Usaha",LRTTOPA!$E$17="Identification No./ Tax Id/Sejenis (Asing)")),TRUE,FALSE)
C32: 23 | D32: LRTTOPA | E32: Jika Jenis Konsumen tidak sesuai dengan Jenis Identitas yang ditentukan, di mana "Individu" hanya dapat memilih NIK/National ID dan "Badan Usaha" hanya dapat memilih NPWP/Identification No./Tax ID/Sejenis | F32: =IF(OR(AND(LRTTOPA!$I$18="individu ",LRTTOPA!$E$18="NIK (Domestik)"),AND(LRTTOPA!$I$18="individu ",LRTTOPA!$E$18="National ID (Asing)"),AND(LRTTOPA!$I$18="Badan Usaha",LRTTOPA!$E$18="NPWP (Domestik)"),AND(LRTTOPA!$I$18="Badan Usaha",LRTTOPA!$E$18="Identification No./ Tax Id/Sejenis (Asing)")),TRUE,FALSE) | G32: =IF(OR(AND(LRTTOPA!$I$18="individu ",LRTTOPA!$E$18="NIK (Domestik)"),AND(LRTTOPA!$I$18="individu ",LRTTOPA!$E$18="National ID (Asing)"),AND(LRTTOPA!$I$18="Badan Usaha",LRTTOPA!$E$18="NPWP (Domestik)"),AND(LRTTOPA!$I$18="Badan Usaha",LRTTOPA!$E$18="Identification No./ Tax Id/Sejenis (Asing)")),TRUE,FALSE)
C33: 24 | D33: LRTTOPA | E33: Jika Jenis Konsumen tidak sesuai dengan Jenis Identitas yang ditentukan, di mana "Individu" hanya dapat memilih NIK/National ID dan "Badan Usaha" hanya dapat memilih NPWP/Identification No./Tax ID/Sejenis | F33: =IF(OR(AND(LRTTOPA!$I$19="individu ",LRTTOPA!$E$19="NIK (Domestik)"),AND(LRTTOPA!$I$19="individu ",LRTTOPA!$E$19="National ID (Asing)"),AND(LRTTOPA!$I$19="Badan Usaha",LRTTOPA!$E$19="NPWP (Domestik)"),AND(LRTTOPA!$I$19="Badan Usaha",LRTTOPA!$E$19="Identification No./ Tax Id/Sejenis (Asing)")),TRUE,FALSE) | G33: =IF(OR(AND(LRTTOPA!$I$19="individu ",LRTTOPA!$E$19="NIK (Domestik)"),AND(LRTTOPA!$I$19="individu ",LRTTOPA!$E$19="National ID (Asing)"),AND(LRTTOPA!$I$19="Badan Usaha",LRTTOPA!$E$19="NPWP (Domestik)"),AND(LRTTOPA!$I$19="Badan Usaha",LRTTOPA!$E$19="Identification No./ Tax Id/Sejenis (Asing)")),TRUE,FALSE)
C34: 25 | D34: LRTTOPA | E34: Jika Jenis Konsumen tidak sesuai dengan Jenis Identitas yang ditentukan, di mana "Individu" hanya dapat memilih NIK/National ID dan "Badan Usaha" hanya dapat memilih NPWP/Identification No./Tax ID/Sejenis | F34: =IF(OR(AND(LRTTOPA!$I$20="individu ",LRTTOPA!$E$20="NIK (Domestik)"),AND(LRTTOPA!$I$20="individu ",LRTTOPA!$E$20="National ID (Asing)"),AND(LRTTOPA!$I$20="Badan Usaha",LRTTOPA!$E$20="NPWP (Domestik)"),AND(LRTTOPA!$I$20="Badan Usaha",LRTTOPA!$E$20="Identification No./ Tax Id/Sejenis (Asing)")),TRUE,FALSE) | G34: =IF(OR(AND(LRTTOPA!$I$20="individu ",LRTTOPA!$E$20="NIK (Domestik)"),AND(LRTTOPA!$I$20="individu ",LRTTOPA!$E$20="National ID (Asing)"),AND(LRTTOPA!$I$20="Badan Usaha",LRTTOPA!$E$20="NPWP (Domestik)"),AND(LRTTOPA!$I$20="Badan Usaha",LRTTOPA!$E$20="Identification No./ Tax Id/Sejenis (Asing)")),TRUE,FALSE)
C35: 26 | D35: LRTTOPA | E35: Jika Jenis Konsumen tidak sesuai dengan Jenis Identitas yang ditentukan, di mana "Individu" hanya dapat memilih NIK/National ID dan "Badan Usaha" hanya dapat memilih NPWP/Identification No./Tax ID/Sejenis | F35: =IF(OR(AND(LRTTOPA!$I$21="individu ",LRTTOPA!$E$21="NIK (Domestik)"),AND(LRTTOPA!$I$21="individu ",LRTTOPA!$E$21="National ID (Asing)"),AND(LRTTOPA!$I$21="Badan Usaha",LRTTOPA!$E$21="NPWP (Domestik)"),AND(LRTTOPA!$I$21="Badan Usaha",LRTTOPA!$E$21="Identification No./ Tax Id/Sejenis (Asing)")),TRUE,FALSE) | G35: =IF(OR(AND(LRTTOPA!$I$21="individu ",LRTTOPA!$E$21="NIK (Domestik)"),AND(LRTTOPA!$I$21="individu ",LRTTOPA!$E$21="National ID (Asing)"),AND(LRTTOPA!$I$21="Badan Usaha",LRTTOPA!$E$21="NPWP (Domestik)"),AND(LRTTOPA!$I$21="Badan Usaha",LRTTOPA!$E$21="Identification No./ Tax Id/Sejenis (Asing)")),TRUE,FALSE)
C36: 27 | D36: LRTTOPA | E36: Jika Jenis Konsumen tidak sesuai dengan Jenis Identitas yang ditentukan, di mana "Individu" hanya dapat memilih NIK/National ID dan "Badan Usaha" hanya dapat memilih NPWP/Identification No./Tax ID/Sejenis | F36: =IF(OR(AND(LRTTOPA!$I$22="individu ",LRTTOPA!$E$22="NIK (Domestik)"),AND(LRTTOPA!$I$22="individu ",LRTTOPA!$E$22="National ID (Asing)"),AND(LRTTOPA!$I$22="Badan Usaha",LRTTOPA!$E$22="NPWP (Domestik)"),AND(LRTTOPA!$I$22="Badan Usaha",LRTTOPA!$E$22="Identification No./ Tax Id/Sejenis (Asing)")),TRUE,FALSE) | G36: =IF(OR(AND(LRTTOPA!$I$22="individu ",LRTTOPA!$E$22="NIK (Domestik)"),AND(LRTTOPA!$I$22="individu ",LRTTOPA!$E$22="National ID (Asing)"),AND(LRTTOPA!$I$22="Badan Usaha",LRTTOPA!$E$22="NPWP (Domestik)"),AND(LRTTOPA!$I$22="Badan Usaha",LRTTOPA!$E$22="Identification No./ Tax Id/Sejenis (Asing)")),TRUE,FALSE)
C37: 28 | D37: LRTTOPA | E37: Jika Jenis Konsumen tidak sesuai dengan Jenis Identitas yang ditentukan, di mana "Individu" hanya dapat memilih NIK/National ID dan "Badan Usaha" hanya dapat memilih NPWP/Identification No./Tax ID/Sejenis | F37: =IF(OR(AND(LRTTOPA!$I$23="individu ",LRTTOPA!$E$23="NIK (Domestik)"),AND(LRTTOPA!$I$23="individu ",LRTTOPA!$E$23="National ID (Asing)"),AND(LRTTOPA!$I$23="Badan Usaha",LRTTOPA!$E$23="NPWP (Domestik)"),AND(LRTTOPA!$I$23="Badan Usaha",LRTTOPA!$E$23="Identification No./ Tax Id/Sejenis (Asing)")),TRUE,FALSE) | G37: =IF(OR(AND(LRTTOPA!$I$23="individu ",LRTTOPA!$E$23="NIK (Domestik)"),AND(LRTTOPA!$I$23="individu ",LRTTOPA!$E$23="National ID (Asing)"),AND(LRTTOPA!$I$23="Badan Usaha",LRTTOPA!$E$23="NPWP (Domestik)"),AND(LRTTOPA!$I$23="Badan Usaha",LRTTOPA!$E$23="Identification No./ Tax Id/Sejenis (Asing)")),TRUE,FALSE)
C38: 29 | D38: LRTTOPA | E38: Jika Jenis Konsumen tidak sesuai dengan Jenis Identitas yang ditentukan, di mana "Individu" hanya dapat memilih NIK/National ID dan "Badan Usaha" hanya dapat memilih NPWP/Identification No./Tax ID/Sejenis | F38: =IF(OR(AND(LRTTOPA!$I$24="individu ",LRTTOPA!$E$24="NIK (Domestik)"),AND(LRTTOPA!$I$24="individu ",LRTTOPA!$E$24="National ID (Asing)"),AND(LRTTOPA!$I$24="Badan Usaha",LRTTOPA!$E$24="NPWP (Domestik)"),AND(LRTTOPA!$I$24="Badan Usaha",LRTTOPA!$E$24="Identification No./ Tax Id/Sejenis (Asing)")),TRUE,FALSE) | G38: =IF(OR(AND(LRTTOPA!$I$24="individu ",LRTTOPA!$E$24="NIK (Domestik)"),AND(LRTTOPA!$I$24="individu ",LRTTOPA!$E$24="National ID (Asing)"),AND(LRTTOPA!$I$24="Badan Usaha",LRTTOPA!$E$24="NPWP (Domestik)"),AND(LRTTOPA!$I$24="Badan Usaha",LRTTOPA!$E$24="Identification No./ Tax Id/Sejenis (Asing)")),TRUE,FALSE)
C39: 30 | D39: LRTTOPA | E39: Jika Jenis Konsumen tidak sesuai dengan Jenis Identitas yang ditentukan, di mana "Individu" hanya dapat memilih NIK/National ID dan "Badan Usaha" hanya dapat memilih NPWP/Identification No./Tax ID/Sejenis | F39: =IF(OR(AND(LRTTOPA!$I$25="individu ",LRTTOPA!$E$25="NIK (Domestik)"),AND(LRTTOPA!$I$25="individu ",LRTTOPA!$E$25="National ID (Asing)"),AND(LRTTOPA!$I$25="Badan Usaha",LRTTOPA!$E$25="NPWP (Domestik)"),AND(LRTTOPA!$I$25="Badan Usaha",LRTTOPA!$E$25="Identification No./ Tax Id/Sejenis (Asing)")),TRUE,FALSE) | G39: =IF(OR(AND(LRTTOPA!$I$25="individu ",LRTTOPA!$E$25="NIK (Domestik)"),AND(LRTTOPA!$I$25="individu ",LRTTOPA!$E$25="National ID (Asing)"),AND(LRTTOPA!$I$25="Badan Usaha",LRTTOPA!$E$25="NPWP (Domestik)"),AND(LRTTOPA!$I$25="Badan Usaha",LRTTOPA!$E$25="Identification No./ Tax Id/Sejenis (Asing)")),TRUE,FALSE)
C40: 31 | D40: LRTTOPA | E40: Jika Jenis Konsumen tidak sesuai dengan Jenis Identitas yang ditentukan, di mana "Individu" hanya dapat memilih NIK/National ID dan "Badan Usaha" hanya dapat memilih NPWP/Identification No./Tax ID/Sejenis | F40: =IF(OR(AND(LRTTOPA!$I$26="individu ",LRTTOPA!$E$26="NIK (Domestik)"),AND(LRTTOPA!$I$26="individu ",LRTTOPA!$E$26="National ID (Asing)"),AND(LRTTOPA!$I$26="Badan Usaha",LRTTOPA!$E$26="NPWP (Domestik)"),AND(LRTTOPA!$I$26="Badan Usaha",LRTTOPA!$E$26="Identification No./ Tax Id/Sejenis (Asing)")),TRUE,FALSE) | G40: =IF(OR(AND(LRTTOPA!$I$26="individu ",LRTTOPA!$E$26="NIK (Domestik)"),AND(LRTTOPA!$I$26="individu ",LRTTOPA!$E$26="National ID (Asing)"),AND(LRTTOPA!$I$26="Badan Usaha",LRTTOPA!$E$26="NPWP (Domestik)"),AND(LRTTOPA!$I$26="Badan Usaha",LRTTOPA!$E$26="Identification No./ Tax Id/Sejenis (Asing)")),TRUE,FALSE)
C41: 32 | D41: LRTTOPA | E41: Jika Jenis Konsumen tidak sesuai dengan Jenis Identitas yang ditentukan, di mana "Individu" hanya dapat memilih NIK/National ID dan "Badan Usaha" hanya dapat memilih NPWP/Identification No./Tax ID/Sejenis | F41: =IF(OR(AND(LRTTOPA!$I$27="individu ",LRTTOPA!$E$27="NIK (Domestik)"),AND(LRTTOPA!$I$27="individu ",LRTTOPA!$E$27="National ID (Asing)"),AND(LRTTOPA!$I$27="Badan Usaha",LRTTOPA!$E$27="NPWP (Domestik)"),AND(LRTTOPA!$I$27="Badan Usaha",LRTTOPA!$E$27="Identification No./ Tax Id/Sejenis (Asing)")),TRUE,FALSE) | G41: =IF(OR(AND(LRTTOPA!$I$27="individu ",LRTTOPA!$E$27="NIK (Domestik)"),AND(LRTTOPA!$I$27="individu ",LRTTOPA!$E$27="National ID (Asing)"),AND(LRTTOPA!$I$27="Badan Usaha",LRTTOPA!$E$27="NPWP (Domestik)"),AND(LRTTOPA!$I$27="Badan Usaha",LRTTOPA!$E$27="Identification No./ Tax Id/Sejenis (Asing)")),TRUE,FALSE)
C42: 33 | D42: LRTTOPA | E42: Jika Jenis Konsumen tidak sesuai dengan Jenis Identitas yang ditentukan, di mana "Individu" hanya dapat memilih NIK/National ID dan "Badan Usaha" hanya dapat memilih NPWP/Identification No./Tax ID/Sejenis | F42: =IF(OR(AND(LRTTOPA!$I$28="individu ",LRTTOPA!$E$28="NIK (Domestik)"),AND(LRTTOPA!$I$28="individu ",LRTTOPA!$E$28="National ID (Asing)"),AND(LRTTOPA!$I$28="Badan Usaha",LRTTOPA!$E$28="NPWP (Domestik)"),AND(LRTTOPA!$I$28="Badan Usaha",LRTTOPA!$E$28="Identification No./ Tax Id/Sejenis (Asing)")),TRUE,FALSE) | G42: =IF(OR(AND(LRTTOPA!$I$28="individu ",LRTTOPA!$E$28="NIK (Domestik)"),AND(LRTTOPA!$I$28="individu ",LRTTOPA!$E$28="National ID (Asing)"),AND(LRTTOPA!$I$28="Badan Usaha",LRTTOPA!$E$28="NPWP (Domestik)"),AND(LRTTOPA!$I$28="Badan Usaha",LRTTOPA!$E$28="Identification No./ Tax Id/Sejenis (Asing)")),TRUE,FALSE)
C43: 34 | D43: LRTTOPA | E43: Jika Jenis Konsumen tidak sesuai dengan Jenis Identitas yang ditentukan, di mana "Individu" hanya dapat memilih NIK/National ID dan "Badan Usaha" hanya dapat memilih NPWP/Identification No./Tax ID/Sejenis | F43: =IF(OR(AND(LRTTOPA!$I$29="individu ",LRTTOPA!$E$29="NIK (Domestik)"),AND(LRTTOPA!$I$29="individu ",LRTTOPA!$E$29="National ID (Asing)"),AND(LRTTOPA!$I$29="Badan Usaha",LRTTOPA!$E$29="NPWP (Domestik)"),AND(LRTTOPA!$I$29="Badan Usaha",LRTTOPA!$E$29="Identification No./ Tax Id/Sejenis (Asing)")),TRUE,FALSE) | G43: =IF(OR(AND(LRTTOPA!$I$29="individu ",LRTTOPA!$E$29="NIK (Domestik)"),AND(LRTTOPA!$I$29="individu ",LRTTOPA!$E$29="National ID (Asing)"),AND(LRTTOPA!$I$29="Badan Usaha",LRTTOPA!$E$29="NPWP (Domestik)"),AND(LRTTOPA!$I$29="Badan Usaha",LRTTOPA!$E$29="Identification No./ Tax Id/Sejenis (Asing)")),TRUE,FALSE)
C44: 35 | D44: LRTTOPA | E44: Jika Jenis Konsumen tidak sesuai dengan Jenis Identitas yang ditentukan, di mana "Individu" hanya dapat memilih NIK/National ID dan "Badan Usaha" hanya dapat memilih NPWP/Identification No./Tax ID/Sejenis | F44: =IF(OR(AND(LRTTOPA!$I$30="individu ",LRTTOPA!$E$30="NIK (Domestik)"),AND(LRTTOPA!$I$30="individu ",LRTTOPA!$E$30="National ID (Asing)"),AND(LRTTOPA!$I$30="Badan Usaha",LRTTOPA!$E$30="NPWP (Domestik)"),AND(LRTTOPA!$I$30="Badan Usaha",LRTTOPA!$E$30="Identification No./ Tax Id/Sejenis (Asing)")),TRUE,FALSE) | G44: =IF(OR(AND(LRTTOPA!$I$30="individu ",LRTTOPA!$E$30="NIK (Domestik)"),AND(LRTTOPA!$I$30="individu ",LRTTOPA!$E$30="National ID (Asing)"),AND(LRTTOPA!$I$30="Badan Usaha",LRTTOPA!$E$30="NPWP (Domestik)"),AND(LRTTOPA!$I$30="Badan Usaha",LRTTOPA!$E$30="Identification No./ Tax Id/Sejenis (Asing)")),TRUE,FALSE)
C45: 36 | D45: LRTTOPA | E45: Jika Jenis Konsumen tidak sesuai dengan Jenis Identitas yang ditentukan, di mana "Individu" hanya dapat memilih NIK/National ID dan "Badan Usaha" hanya dapat memilih NPWP/Identification No./Tax ID/Sejenis | F45: =IF(OR(AND(LRTTOPA!$I$31="individu ",LRTTOPA!$E$31="NIK (Domestik)"),AND(LRTTOPA!$I$31="individu ",LRTTOPA!$E$31="National ID (Asing)"),AND(LRTTOPA!$I$31="Badan Usaha",LRTTOPA!$E$31="NPWP (Domestik)"),AND(LRTTOPA!$I$31="Badan Usaha",LRTTOPA!$E$31="Identification No./ Tax Id/Sejenis (Asing)")),TRUE,FALSE) | G45: =IF(OR(AND(LRTTOPA!$I$31="individu ",LRTTOPA!$E$31="NIK (Domestik)"),AND(LRTTOPA!$I$31="individu ",LRTTOPA!$E$31="National ID (Asing)"),AND(LRTTOPA!$I$31="Badan Usaha",LRTTOPA!$E$31="NPWP (Domestik)"),AND(LRTTOPA!$I$31="Badan Usaha",LRTTOPA!$E$31="Identification No./ Tax Id/Sejenis (Asing)")),TRUE,FALSE)
C46: 37 | D46: LRTTOPA | E46: Jika Jenis Konsumen tidak sesuai dengan Jenis Identitas yang ditentukan, di mana "Individu" hanya dapat memilih NIK/National ID dan "Badan Usaha" hanya dapat memilih NPWP/Identification No./Tax ID/Sejenis | F46: =IF(OR(AND(LRTTOPA!$I$32="individu ",LRTTOPA!$E$32="NIK (Domestik)"),AND(LRTTOPA!$I$32="individu ",LRTTOPA!$E$32="National ID (Asing)"),AND(LRTTOPA!$I$32="Badan Usaha",LRTTOPA!$E$32="NPWP (Domestik)"),AND(LRTTOPA!$I$32="Badan Usaha",LRTTOPA!$E$32="Identification No./ Tax Id/Sejenis (Asing)")),TRUE,FALSE) | G46: =IF(OR(AND(LRTTOPA!$I$32="individu ",LRTTOPA!$E$32="NIK (Domestik)"),AND(LRTTOPA!$I$32="individu ",LRTTOPA!$E$32="National ID (Asing)"),AND(LRTTOPA!$I$32="Badan Usaha",LRTTOPA!$E$32="NPWP (Domestik)"),AND(LRTTOPA!$I$32="Badan Usaha",LRTTOPA!$E$32="Identification No./ Tax Id/Sejenis (Asing)")),TRUE,FALSE)
C47: 38 | D47: LRTTOPA | E47: Jika Jenis Konsumen tidak sesuai dengan Jenis Identitas yang ditentukan, di mana "Individu" hanya dapat memilih NIK/National ID dan "Badan Usaha" hanya dapat memilih NPWP/Identification No./Tax ID/Sejenis | F47: =IF(OR(AND(LRTTOPA!$I$33="individu ",LRTTOPA!$E$33="NIK (Domestik)"),AND(LRTTOPA!$I$33="individu ",LRTTOPA!$E$33="National ID (Asing)"),AND(LRTTOPA!$I$33="Badan Usaha",LRTTOPA!$E$33="NPWP (Domestik)"),AND(LRTTOPA!$I$33="Badan Usaha",LRTTOPA!$E$33="Identification No./ Tax Id/Sejenis (Asing)")),TRUE,FALSE) | G47: =IF(OR(AND(LRTTOPA!$I$33="individu ",LRTTOPA!$E$33="NIK (Domestik)"),AND(LRTTOPA!$I$33="individu ",LRTTOPA!$E$33="National ID (Asing)"),AND(LRTTOPA!$I$33="Badan Usaha",LRTTOPA!$E$33="NPWP (Domestik)"),AND(LRTTOPA!$I$33="Badan Usaha",LRTTOPA!$E$33="Identification No./ Tax Id/Sejenis (Asing)")),TRUE,FALSE)
...

Sheet LKBPAKD
B2: LKBPAKD
B3: 1
C7: =UPPER('Data Umum'!D7)
C8: PEDAGANG ASET KEUANGAN DIGITAL
C9: Laporan Bulanan
C10: Laporan Kegiatan Bulanan Pedagang
C11: ="Per " & TEXT('Data Umum'!D11, "DD-MMM-YYYY")
C14: Nomor | E14: ="Individu" | G14: ="Badan Usaha" | I14: =""
E15: ="WNI" | F15: ="WNA" | G15: ="Domestik" | H15: ="Internasional" | I15: ="Total"
C16: Jumlah Konsumen (awal bulan) | E16: 1044622 | F16: 38 | G16: - | H16: - | I16: =SUM(E16:H16)
C17: Jumlah Penambahan Konsumen | E17: 41522 | F17: - | G17: - | H17: - | I17: =SUM(E17:H17)
C18: Jumlah Pengurangan Konsumen | E18: - | F18: - | G18: - | H18: - | I18: =SUM(E18:H18)
C19: Jumlah Konsumen (Akhir Bulan) | E19: 1086144 | F19: 38 | G19: - | H19: - | I19: =SUM(E19:H19)

Sheet LRTTHP
B2: LRTTHP
B3: 1
C7: =UPPER('Data Umum'!D7)
C8: PEDAGANG ASET KEUANGAN DIGITAL
C9: Laporan Bulanan
C10: Rekapitulasi Top 20 Konsumen Berdasarkan Nilai Transaksi Harian Per Pedagang
C11: ="Per " & TEXT('Data Umum'!D11, "DD-MMM-YYYY")
C14: Nomor | E14: ="Jenis Identitas" | F14: ="No Identitas" | G14: ="Nama" | H14: ="Kategori Konsumen" | I14: ="Jenis Konsumen" | J14: ="Nilai Transaksi* (Rp)"
C16: 1 | E16: NIK (Domestik) | F16: 3273030510730006 | G16: UNTUNG SETIAWAN | H16: Domestik | I16: Individu | J16: 4.858038e+09
C17: 2 | E17: NIK (Domestik) | F17: 3273034112820002 | G17: SRI WIDIANTI | H17: Domestik | I17: Individu | J17: 4.4146772e+09
C18: 3 | E18: NIK (Domestik) | F18: 3505171011890004 | G18: RONNY DALTON | H18: Domestik | I18: Individu | J18: 3.5795028e+09
C19: 4 | E19: NIK (Domestik) | F19: 3604012212740033 | G19: MOHAMMAD NURKHOLIK | H19: Domestik | I19: Individu | J19: 3.0092753e+09
C20: 5 | E20: NIK (Domestik) | F20: 3323091012750001 | G20: DWI HANUNG PRASETYO | H20: Domestik | I20: Individu | J20: 1.7313842e+09
C21: 6 | E21: NIK (Domestik) | F21: 3273037108930004 | G21: RISKA KOMALA SARI | H21: Domestik | I21: Individu | J21: 1.7306059e+09
C22: 7 | E22: NIK (Domestik) | F22: 3215033010720002 | G22: SUBCHAN, SPD | H22: Domestik | I22: Individu | J22: 1.6472624e+09
C23: 8 | E23: NIK (Domestik) | F23: 3173061411790007 | G23: MARCELL WILLIAM | H23: Domestik | I23: Individu | J23: 1.5051756e+09
C24: 9 | E24: NIK (Domestik) | F24: 5171015409740004 | G24: PUTU HERLINA | H24: Domestik | I24: Individu | J24: 1.4352762e+09
C25: 10 | E25: NIK (Domestik) | F25: 3174020109730006 | G25: ARIEF BUDIANTO | H25: Domestik | I25: Individu | J25: 1.260707e+09
C26: 11 | E26: NIK (Domestik) | F26: 3175010211800003 | G26: WIRYANTO WIJAYA | H26: Domestik | I26: Individu | J26: 1.1615845e+09
C27: 12 | E27: NIK (Domestik) | F27: 3671054807750010 | G27: SURIATI | H27: Domestik | I27: Individu | J27: 1.1477142e+09
... C35: 20 | E35: NIK (Domestik) | F35: 1501021001840003 | G35: IWAN PELANI | H35: Domestik | I35: Individu | J35: 707219222
C36: Total | E36: ="" | F36: ="" | G36: ="" | H36: ="" | I36: ="" | J36: =SUM(J16:J35)

Sheet LRTTOPA
B2: LRTTOPA
B3: 1
C7: =UPPER('Data Umum'!D7)
C8: PEDAGANG ASET KEUANGAN DIGITAL
C9: Laporan Bulanan
C10: Rekapitulasi Top 20 Konsumen Berdasarkan Nilai Top Up Dana Fiat
C11: ="Per " & TEXT('Data Umum'!D11, "DD-MMM-YYYY")
C14: Nomor | E14: ="Jenis Identitas" | F14: ="No Identitas" | G14: ="Nama" | H14: ="Kategori Konsumen" | I14: ="Jenis Konsumen" | J14: ="Nilai Top Up (Rp)"
C16: 1 | E16: NIK (Domestik) | F16: 3173061411790007 | G16: MARCELL WILLIAM | I16: Individu | J16: 760000000
C17: 2 | E17: NIK (Domestik) | F17: 3173040806830005 | G17: JOHAN CHANDRA | I17: Individu | J17: 300000000
C18: 3 | E18: NIK (Domestik) | F18: 3172015411810010 | G18: WINCE SUDARTO | I18: Individu | J18: 250000000
C19: 4 | E19: NIK (Domestik) | F19: 1271060309900001 | G19: TONY | I19: Individu | J19: 227450637
C20: 5 | E20: NIK (Domestik) | F20: 1202091403040001 | G20: HABIB FATIH ROJHAN | I20: Individu | J20: 200000000
C21: 6 | E21: NIK (Domestik) | F21: 1971050806700004 | G21: ROBERTUS BAMBANG SUSILO | I21: Individu | J21: 170000000
C22: 7 | E22: NIK (Domestik) | F22: 3273032505450002 | G22: ATIM EFENDI | I22: Individu | J22: 120000000
C23: 8 | E23: NIK (Domestik) | F23: 3573032503900003 | G23: MARIO FERNANDO | I23: Individu | J23: 120000000
C24: 9 | E24: NIK (Domestik) | F24: 7171066604670001 | G24: ASNIAR | I24: Individu | J24: 115000000
C25: 10 | E25: NIK (Domestik) | F25: 1302122710850002 | G25: RENGGA GENI AKHSAN ANIS | I25: Individu | J25: 100000000
C26: 11 | E26: NIK (Domestik) | F26: 3173010609950001 | G26: NATHANIEL CHRISTIANTO HARTANTO | I26: Individu | J26: 100000000
C27: 12 | E27: NIK (Domestik) | F27: 1471060307010002 | G27: WILSON ROYNANDO PANJAITAN | I27: Individu | J27: 97636122
... C35: 20 | E35: NIK (Domestik) | F35: 3578312108730001 | G35: AGUS SUGIHARTO | I35: Individu | J35: 60000000
C36: Total | E36: ="" | F36: ="" | G36: ="" | H36: ="" | I36: ="" | J36: =SUM(J16:J35)

Sheet LRTNWDA
B2: LRTNWDA
B3: 1
C7: =UPPER('Data Umum'!D7)
C8: PEDAGANG ASET KEUANGAN DIGITAL
C9: Laporan Bulanan
C10: Rekapitulasi Top 20 Konsumen Berdasarkan Nilai Withdraw Dana Fiat
C11: ="Per " & TEXT('Data Umum'!D11, "DD-MMM-YYYY")
C14: Nomor | E14: ="Jenis Identitas" | F14: ="No Identitas" | G14: ="Nama" | H14: ="Kategori Konsumen" | I14: ="Jenis Konsumen" | J14: ="Nilai Withdraw (Rp)"
C16: 1 | E16: National ID (Asing) | F16: PB5653059 | G16: JENNIFER JOAN DUMMETT | H16: Asing | I16: Individu | J16: 562690980
C17: 2 | E17: NIK (Domestik) | F17: 3275092905810013 | G17: SIMONTA TUAN | H17: Domestik | I17: Individu | J17: 497367317
C18: 3 | E18: NIK (Domestik) | F18: 3173040806830005 | G18: JOHAN CHANDRA | H18: Domestik | I18: Individu | J18: 364330603
C19: 4 | E19: NIK (Domestik) | F19: 3173061411790007 | G19: MARCELL WILLIAM | H19: Domestik | I19: Individu | J19: 253226262
C20: 5 | E20: NIK (Domestik) | F20: 1501021001840003 | G20: IWAN PELANI | H20: Domestik | I20: Individu | J20: 230004500
C21: 6 | E21: NIK (Domestik) | F21: 3173084401650001 | G21: RAMAWATI ARIFIN | H21: Domestik | I21: Individu | J21: 225800000
C22: 7 | E22: NIK (Domestik) | F22: 1671040904840021 | G22: M. CHARNAIN IBRAHIM | H22: Domestik | I22: Individu | J22: 201685287
C23: 8 | E23: NIK (Domestik) | F23: 3578232211970001 | G23: MUHAMMAD AMIN | H23: Domestik | I23: Individu | J23: 200137309
C24: 9 | E24: NIK (Domestik) | F24: 3505171011890004 | G24: RONNY DALTON | H24: Domestik | I24: Individu | J24: 180892199
C25: 10 | E25: NIK (Domestik) | F25: 3374021502830001 | G25: HADI CHANDRA | H25: Domestik | I25: Individu | J25: 179972438
C26: 11 | E26: NIK (Domestik) | F26: 6303051207940008 | G26: MUHAMMAD BAIHAKI | H26: Domestik | I26: Individu | J26: 167107563
C27: 12 | E27: NIK (Domestik) | F27: 3172012304710004 | G27: JIMMY HUNGIANTO | H27: Domestik | I27: Individu | J27: 159020051
... C35: 20 | E35: NIK (Domestik) | F35: 7471011810750002 | G35: IMAN MANGORI | H35: Domestik | I35: Individu | J35: 88200000
C36: Total | E36: ="" | F36: ="" | G36: ="" | H36: ="" | I36: ="" | J36: =SUM(J16:J35)

Sheet Values
B1: Badan Usaha | C1: Individu | D1: Kategori Konsumen
B2: NPWP (Domestik) | C2: NIK (Domestik) | D2: Asing
B3: Identification No./ Tax Id/Sejenis (Asing) | C3: National ID (Asing) | D3: Domestik
